<?xml version="1.0" ?>
<robot xmlns:xacro="http://www.ros.org/wiki/xacro" name="firefighter">
  <xacro:property name="width" value=".2" />
  <link name="world"/>
  <joint name="world_joint" type="fixed">
    <parent link="world" />
    <child link="base" />
  </joint>

  <link name="base">
    <visual>
      <geometry>
        <mesh filename="package://mycobot_description/urdf/320_urdf/base.dae" />
      </geometry>
      <origin xyz="0 0 0 " rpy=" 0 0 0" />
    </visual>
    <collision>
      <origin xyz="0 0 0.05 " rpy=" 0 0 0" />
      <geometry>
        <cylinder length="0.102" radius="0.0725" />
      </geometry>
    </collision>
    <inertial>
      <mass value="0.92353" />
      <inertia ixx="1.0" ixy="0.0" ixz="0.0" iyy="1.0" iyz="0.0" izz="1.0" />
    </inertial>
  </link>

  <link name="link1">
    <visual>
      <geometry>
        <mesh filename="package://mycobot_description/urdf/320_urdf/link1.dae" />
      </geometry>
      <origin xyz="0 0 0 " rpy=" 0 0 0" />
    </visual>
    <collision>
      <origin xyz="0 0 -0.02 " rpy=" 0 0 0" />
      <geometry>
        <cylinder length="0.106" radius="0.043" />
      </geometry>
    </collision>
    <inertial>
      <mass value="0.3331" />
      <inertia ixx="1.0" ixy="0.0" ixz="0.0" iyy="1.0" iyz="0.0" izz="1.0" />
    </inertial>
  </link>

  <link name="link2">
    <visual>
      <geometry>
        <mesh filename="package://mycobot_description/urdf/320_urdf/link2.dae" />
      </geometry>
      <origin xyz="0 0 0.0587 " rpy=" 0 0 3.1415926" />
    </visual>
    <collision>
      <origin xyz="0.07 0 0.095 " rpy=" 0 -1.5708 0" />
      <geometry>
        <cylinder length="0.18" radius="0.036" />
      </geometry>
    </collision>
    <inertial>
      <mass value="0.29389" />
      <inertia ixx="1.0" ixy="0.0" ixz="0.0" iyy="1.0" iyz="0.0" izz="1.0" />
    </inertial>
  </link>

  <link name="link3">
    <visual>
      <geometry>
        <mesh filename="package://mycobot_description/urdf/320_urdf/link3.dae" />
      </geometry>
      <origin xyz="0 0 0.038 " rpy=" 0 0 3.1415926" />
    </visual>
    <collision>
      <origin xyz="0.044 0 0 " rpy=" 0 -1.5708 0" />
      <geometry>
        <cylinder length="0.14" radius="0.0305" />
      </geometry>
    </collision>
    <inertial>
      <mass value="0.41605" />
      <inertia ixx="1.0" ixy="0.0" ixz="0.0" iyy="1.0" iyz="0.0" izz="1.0" />
    </inertial>
  </link>

  <link name="link4">
    <visual>
      <geometry>
        <mesh filename="package://mycobot_description/urdf/320_urdf/link4.dae" />
      </geometry>
      <origin xyz="0 -0.001 0 " rpy=" 0 0 0" />
    </visual>
    <collision>
      <origin xyz="0.0 -0.014 0 " rpy=" 0 -1.5708 1.5708" />
      <geometry>
        <cylinder length="0.083" radius="0.029" />
      </geometry>
    </collision>
    <inertial>
      <mass value="0.18777" />
      <inertia ixx="1.0" ixy="0.0" ixz="0.0" iyy="1.0" iyz="0.0" izz="1.0" />
    </inertial>
  </link>

  <link name="link5">
    <visual>
      <geometry>
        <mesh filename="package://mycobot_description/urdf/320_urdf/link5.dae" />
      </geometry>
      <origin xyz="0 0.002  0 " rpy=" 0  0 3.1415926" />
    </visual>
    <collision>
      <origin xyz="0 -0.01 0 " rpy=" 1.5708 1.5708 0" />
      <geometry>
        <cylinder length="0.0849" radius="0.029" />
      </geometry>
    </collision>
    <inertial>
      <mass value="0.22519" />
      <inertia ixx="1.0" ixy="0.0" ixz="0.0" iyy="1.0" iyz="0.0" izz="1.0" />
    </inertial>
  </link>

  <link name="link6">
    <visual>
      <geometry>
        <cylinder length="0.02" radius="0.026" />
      </geometry>
      <material name="grey">
        <color rgba="0.5 0.5 0.5 1" />
      </material>
      <origin xyz="0 0 -0.01 " rpy=" 0 0 0" />
    </visual>
    <collision>
      <origin xyz="0.0 0 -0.01 " rpy=" 0 0 0" />
      <geometry>
        <cylinder length="0.0225" radius="0.026" />
      </geometry>
    </collision>
    <inertial>
      <mass value="0.060102" />
      <inertia ixx="1.0" ixy="0.0" ixz="0.0" iyy="1.0" iyz="0.0" izz="1.0" />
    </inertial>
  </link>

  <joint name="joint2_to_joint1" type="revolute">
    <axis xyz="0 0 1" />
    <limit lower="-2.97" upper="2.97" effort="1000" velocity="3.14" />
    <parent link="base" />
    <child link="link1" />
    <origin xyz="0 0 0.17846" rpy="0 0 0" />
  </joint>

  <joint name="joint3_to_joint2" type="revolute">
    <axis xyz="0 0 1" />
    <limit lower="-2.79" upper="2.79" effort="1000" velocity="3.14" />
    <parent link="link1" />
    <child link="link2" />
    <origin xyz="0 0  0" rpy="0 -1.57080  1.57080" />
  </joint>

  <joint name="joint4_to_joint3" type="revolute">
    <axis xyz=" 0 0 1" />
    <limit lower="-2.79" upper="2.79" effort="1000" velocity="3.14" />
    <parent link="link2" />
    <child link="link3" />
    <origin xyz="0.13635 0 0   " rpy="0 0 0" />
  </joint>

  <joint name="joint5_to_joint4" type="revolute">
    <axis xyz=" 0 0 1" />
    <limit lower="-2.79" upper="2.79" effort="1000" velocity="3.14" />
    <parent link="link3" />
    <child link="link4" />
    <origin xyz="0.1 0  0.090" rpy="0 0 1.57080" />
  </joint>

  <joint name="joint6_to_joint5" type="revolute">
    <axis xyz="0 0 1" />
    <limit lower="-2.97" upper="2.97" effort="1000" velocity="3.14" />
    <parent link="link4" />
    <child link="link5" />
    <origin xyz="0 -0.08515 0" rpy="1.57080 -1.57080 0" />
  </joint>

  <joint name="joint6output_to_joint6" type="revolute">
    <axis xyz="0 0 1" />
    <limit lower="-3.05" upper="3.05" effort="1000" velocity="3.14" />
    <parent link="link5" />
    <child link="link6" />
    <origin xyz="0 0.06 0" rpy="-1.57080 0 0 " />
  </joint>

  <!-- Transmission -->
  <transmission name="trans_joint2_to_joint1">
    <type>transmission_interface/SimpleTransmission</type>
    <joint name="joint2_to_joint1">
      <hardwareInterface>hardware_interface/EffortJointInterface</hardwareInterface>
    </joint>
    <actuator name="joint2_to_joint1_motor">
      <hardwareInterface>hardware_interface/EffortJointInterface</hardwareInterface>
      <mechanicalReduction>1</mechanicalReduction>
    </actuator>
  </transmission>

  <transmission name="trans_joint3_to_joint2">
    <type>transmission_interface/SimpleTransmission</type>
    <joint name="joint3_to_joint2">
      <hardwareInterface>hardware_interface/EffortJointInterface</hardwareInterface>
    </joint>
    <actuator name="joint3_to_joint2_motor">
      <hardwareInterface>hardware_interface/EffortJointInterface</hardwareInterface>
      <mechanicalReduction>1</mechanicalReduction>
    </actuator>
  </transmission>

  <transmission name="trans_joint4_to_joint3">
    <type>transmission_interface/SimpleTransmission</type>
    <joint name="joint4_to_joint3">
      <hardwareInterface>hardware_interface/EffortJointInterface</hardwareInterface>
    </joint>
    <actuator name="joint4_to_joint3_motor">
      <hardwareInterface>hardware_interface/EffortJointInterface</hardwareInterface>
      <mechanicalReduction>1</mechanicalReduction>
    </actuator>
  </transmission>

  <transmission name="trans_joint5_to_joint4">
    <type>transmission_interface/SimpleTransmission</type>
    <joint name="joint5_to_joint4">
      <hardwareInterface>hardware_interface/EffortJointInterface</hardwareInterface>
    </joint>
    <actuator name="joint5_to_joint4_motor">
      <hardwareInterface>hardware_interface/EffortJointInterface</hardwareInterface>
      <mechanicalReduction>1</mechanicalReduction>
    </actuator>
  </transmission>

  <transmission name="trans_joint6_to_joint5">
    <type>transmission_interface/SimpleTransmission</type>
    <joint name="joint6_to_joint5">
      <hardwareInterface>hardware_interface/EffortJointInterface</hardwareInterface>
    </joint>
    <actuator name="joint6_to_joint5_motor">
      <hardwareInterface>hardware_interface/EffortJointInterface</hardwareInterface>
      <mechanicalReduction>1</mechanicalReduction>
    </actuator>
  </transmission>

  <transmission name="trans_joint6output_to_joint6">
    <type>transmission_interface/SimpleTransmission</type>
    <joint name="joint6output_to_joint6">
      <hardwareInterface>hardware_interface/EffortJointInterface</hardwareInterface>
    </joint>
    <actuator name="joint6output_to_joint6_motor">
      <hardwareInterface>hardware_interface/EffortJointInterface</hardwareInterface>
      <mechanicalReduction>1</mechanicalReduction>
    </actuator>
  </transmission>

  <gazebo>
    <plugin name="gazebo_ros_control" filename="libgazebo_ros_control.so">
      <robotNamespace>/</robotNamespace>
    </plugin>
  </gazebo>
</robot>